<?xml version='1.0'?>
<sdf version='1.4'>
  <model name="robi">
	<static>false</static>	<!-->set to false after joints and positioning is defined, then inertias will work correct<!-->

	<link name="chassis">
		<pose>0 0 .012 0 0 0</pose>
		<inertial>
			<pose>0 0.001 0 0 0 0</pose>
      			<inertia>
        			<!--><ixx>0.000143414</ixx>
        			<iyy>0.000115030</iyy>
        			<izz>0.000258336</izz>
				<ixy>-0.0000000657706</ixy>
				<ixz>0.00000000019534</ixz>
				<iyz>0.00000000072647</iyz>
      			</inertia>
      			<mass>0.06432</mass><!-->
				<ixx>0.143414</ixx>
        			<iyy>0.115030</iyy>
        			<izz>0.258336</izz>
				<ixy>-0.0000657706</ixy>
				<ixz>0.00000019534</ixz>
				<iyz>0.00000072647</iyz>
      			</inertia>
      			<mass>64.32</mass>
		</inertial>
		<collision name='collision'>
              		<geometry>
                		<cylinder>
                  			<radius>0.09</radius>
					<length>0.002</length>
                		</cylinder>
              		</geometry>
            	</collision>

            	<visual name='visual'>
			<pose>0 0 0.001 0 0 0</pose>
              		<geometry>
                		<mesh>
					<uri>model://gazebo-robi/meshes/robi_base2.dae</uri>
     				</mesh>
              		</geometry>
			<!--><geometry>
                		<cylinder>
                  			<radius>0.09</radius>
					<length>0.002</length>
                		</cylinder>
              		</geometry><!-->
            	</visual>

		<collision name='caster_collision'>
			<pose>0 0.07 0 0 0 0</pose>
			<geometry>
                		<sphere>
                			<radius>.012</radius>
              			</sphere>
            		</geometry>

            		<surface>
              			<friction>
                			<ode>
                  				<mu>0</mu>
                  				<mu2>0</mu2>
                  				<slip1>1.0</slip1>
                  				<slip2>1.0</slip2>
                			</ode>
              			</friction>
            		</surface>
          	</collision>

		<inertial>
      			<inertia>
					<!--><ixx>0.000001163213</ixx>
					<iyy>0.000001163213</iyy>
					<izz>0.000001163213</izz>
					<ixy>0</ixy>
					<ixz>0</ixz>
					<iyz>0</iyz>
	      			</inertia>
	      			<mass>0.02019466</mass><!-->
					<ixx>0.001163213</ixx>
					<iyy>0.001163213</iyy>
					<izz>0.001163213</izz>
					<ixy>0</ixy>
					<ixz>0</ixz>
					<iyz>0</iyz>
      			</inertia>
      			<mass>20.19466</mass>
		</inertial>

          	<visual name='caster_visual'>
            		<pose>0 0.07 0 0 0 0</pose>

            		<geometry>
              			<sphere>
                			<radius>.012</radius>
              			</sphere>
            		</geometry>
          	</visual>

		<collision name='battery_collision'>
            		<pose>0 0.04 0 0 0 0</pose>
				<geometry>
                			<box>
                				<size>.02 .01 .005</size>
              				</box>
            			</geometry>
          		</collision>

		<inertial>
	      		<inertia>
				<!--><ixx>0.000001163213</ixx>
					<iyy>0.000001163213</iyy>
					<izz>0.000001163213</izz>
					<ixy>0</ixy>
					<ixz>0</ixz>
					<iyz>0</iyz>
	      			</inertia>
	      			<mass>0.02019466</mass><!-->
				<ixx>0.001163213</ixx>
				<iyy>0.001163213</iyy>
				<izz>0.001163213</izz>
				<ixy>0</ixy>
				<ixz>0</ixz>
				<iyz>0</iyz>
	      		</inertia>
	      		<mass>20.19466</mass>
		</inertial>

		<visual name='battery_visual'>
            		<pose>0 0.04 0 0 0 0</pose>

            		<geometry>
              			<box>
                			<size>.02 .01 .005</size>
              			</box>
            		</geometry>
          	</visual>
	</link>

	  <link name="left_wheel">
        	<pose>0.082 0 0.012 0 1.5707 0</pose>
		<inertial>
			<pose>0 0 0 0 0 0</pose>
      			<!--><mass>0.010097</mass>
      			<inertia>
        			<ixx>0.000000578914</ixx>
        			<iyy>0.000000578914</iyy>
        			<izz>0.000000727008</izz>
				<ixy>0</ixy>
				<ixz>0</ixz>
				<iyz>0</iyz>
      			</inertia><!-->
			<mass>10.097</mass>
      			<inertia>
        			<ixx>0.000578914</ixx>
        			<iyy>0.000578914</iyy>
        			<izz>0.000727008</izz>
				<ixy>0</ixy>
				<ixz>0</ixz>
				<iyz>0</iyz>
      			</inertia>
		</inertial>
        	<collision name="collision">
         		<geometry>
            			<cylinder>
              				<radius>.012</radius>
              				<length>.008</length>
            			</cylinder>
          		</geometry>
			<surface>
				<friction>
				  <ode><mu>100000.0</mu><mu2>100000.0</mu2></ode>
				</friction>
			</surface>
        	</collision>
        	<visual name="visual">
        		<geometry>
            			<cylinder>
              				<radius>.012</radius>
              				<length>.008</length>
            			</cylinder>
          		</geometry>
        	</visual>
     	  </link>
	  <link name="right_wheel">
        	<pose>-0.082 0 0.012 0 1.5707 0</pose>
		<inertial>
			<pose>0 0 0 0 0 0</pose>
      			<!--><mass>0.010097</mass>
      			<inertia>
        			<ixx>0.000000578914</ixx>
        			<iyy>0.000000578914</iyy>
        			<izz>0.000000727008</izz>
				<ixy>0</ixy>
				<ixz>0</ixz>
				<iyz>0</iyz>
      			</inertia><!-->
			<mass>10.097</mass>
      			<inertia>
        			<ixx>0.000578914</ixx>
        			<iyy>0.000578914</iyy>
        			<izz>0.000727008</izz>
				<ixy>0</ixy>
				<ixz>0</ixz>
				<iyz>0</iyz>
      			</inertia>
		</inertial>
        	<collision name="collision">
         		<geometry>
            			<cylinder>
              				<radius>.012</radius>
              				<length>.008</length>
            			</cylinder>
          		</geometry>
			<surface>
				<friction>
				  <ode><mu>100000.0</mu><mu2>100000.0</mu2></ode>
				</friction>
			</surface>
        	</collision>
        	<visual name="visual">
        		<geometry>
            			<cylinder>
              				<radius>.012</radius>
              				<length>.008</length>
            			</cylinder>
          		</geometry>
        	</visual>
     	  </link>
	
	<joint type="revolute" name="left_wheel_hinge">
        	<pose>0 0 0.012 0 0 0</pose>
        	<child>left_wheel</child>
        	<parent>chassis</parent>
        	<axis>
          		<xyz>1 0 0</xyz>
			<limit>
				<lower>-10000000000000000</lower>
      				<upper>10000000000000000</upper>
    			</limit>
        	</axis>
      	</joint>

      	<joint type="revolute" name="right_wheel_hinge">
        	<pose>0 0 0.012 0 0 0</pose>
        	<child>right_wheel</child>
        	<parent>chassis</parent>
        	<axis>
          		<xyz>1 0 0</xyz>
 			<limit>
				<lower>-10000000000000000</lower>
      				<upper>10000000000000000</upper>
    			</limit>
        	</axis>
      	</joint>

  </model>
</sdf>
